Workbook
Name ACTION: #REF!

Sheet Cover
C2: TEST CASE
B4: Project Name | C4: <Project Name> | F4: Creator
B5: Project Code | C5: <Project Code> | F5: Reviewer/Approver
B6: Document Code | C6: =C5&"_"&"XXX"&"_"&"vx.x" -> <Project Code>_XXX_vx.x | F6: Issue Date
F7: Version
B10: Record of change
B11: Effective Date | C11: Version | D11: Change Item | E11: *A,D,M | F11: Change description | G11: Reference
B12: <Date when these changes are effective> | G12: <List of documents which are refered in this version.>

Sheet Test case List
D1: TEST CASE LIST
B3: Project Name | D3: =Cover!C4 -> <Project Name>
B4: Project Code | D4: =Cover!C5 -> <Project Code>
B5: Test Environment Setup Description | D5: <List enviroment requires in this system 1. Server 2. Database 3. Web Browser ... >
B8: No | C8: Function Name | D8: Sheet Name | E8: Description | F8: Pre-Condition
B9: 1 | C9: Function A | D9: Module1
B10: 2 | C10: Function B | D10: Module1
B11: 3 | C11: Function C | D11: Module1
B12: 4 | C12: Function D | D12: Module2
B13: 5 | C13: Function E | D13: Module2

Sheet BC
A2: Module Code | B2: Module1 | K2: Pass
A3: Test requirement | B3: <Brief description about requirements which are tested in this sheet> | K3: Fail
A4: Tester
A5: Pass | B5: Fail | C5: Untested | D5: N/A | E5: Number of Test cases | K5: Untesed
A6: =COUNTIF(G10:G998,"Pass") -> 0 | B6: =COUNTIF(G10:G998,"Fail") -> 0 | C6: =E6-D6-B6-A6 -> 6 | D6: =COUNTIF(G$10:G$998,"N/A") -> 0 | E6: =COUNTA(A10:A998) -> 6 | K6: N/A
A8: ID | B8: Test Case Description | C8: Test Case Procedure | D8: Expected Output | E8: Inter-test case Dependence | F8: TestData | G8: Result | H8: Test date | I8: Note
B9: Function A
A10: =IF(OR(B10<>"",D10<>""),"["&TEXT($B$2,"##")&"-"&TEXT(ROW()-10,"##")&"]","") -> [Module1 -] | B10: <Brief description of this case: what is tested?> Ex: Test viewing "Company" form. | C10: <Describe steps to perform this case> Ex: 1. Login the system with Manager role. 2. Click "Company" tab in the left menu. | D10: <Describe results which meet customer's requirement> Ex: 1. The Hompage is displayed 2. The "Company" view form is displayed with the folowing informations: - Company name - Company address - Phone - Fax | E10: <List all test cases or conditions that must be done before performing this case>
A11: =IF(OR(B11<>"",D11<>""),"["&TEXT($B$2,"##")&"-"&TEXT(ROW()-10,"##")&"]","") -> [Module1 -1] | B11: <Test case 2>
A12: =IF(OR(B12<>"",D12<>""),"["&TEXT($B$2,"##")&"-"&TEXT(ROW()-10,"##")&"]","") -> [Module1 -2] | B12: <Test case 3>
B13: Function B
A14: =IF(OR(B14<>"",D14<>""),"["&TEXT($B$2,"##")&"-"&TEXT(ROW()-11,"##")&"]","") -> [Module1 -3] | B14: <Test case 4>
A15: =IF(OR(B15<>"",D15<>""),"["&TEXT($B$2,"##")&"-"&TEXT(ROW()-11,"##")&"]","") -> [Module1 -4] | B15: <Test case 5>
B16: Function C
A17: =IF(OR(B17<>"",D17<>""),"["&TEXT($B$2,"##")&"-"&TEXT(ROW()-12,"##")&"]","") -> [Module1 -5] | B17: <Test case 6>

Sheet Test Report
B1: TEST REPORT
B3: Project Name | C3: =Cover!C4 -> <Project Name> | E3: Creator
B4: Project Code | C4: =Cover!C5 -> <Project Code> | E4: Reviewer/Approver
B5: Document Code | C5: =C4&"_"&"Test Report"&"_"&"vx.x" -> <Project Code>_Test Report_vx.x | E5: Issue Date | H5: <Date when this test report is created>
B6: Notes | C6: <List modules included in this release> ex: Release 1 includes 2 modules: Module1 and Module2
B10: No | C10: Module code | D10: Pass | E10: Fail | F10: Untested | G10: N/A | H10: Number of test cases
B11: 1 | C11: =BC!B2 -> Module1 | D11: =BC!A6 -> 0 | E11: =BC!B6 -> 0 | F11: =BC!C6 -> 6 | G11: =BC!D6 -> 0 | H11: =BC!E6 -> 6
B12: 2 | C12: =#REF! -> #REF! | D12: =#REF! -> #REF! | E12: =#REF! -> #REF! | F12: =#REF! -> #REF! | G12: =#REF! -> #REF! | H12: =#REF! -> #REF!
C14: Sub total | D14: =SUM(D9:D13) -> #REF! | E14: =SUM(E9:E13) -> #REF! | F14: =SUM(F9:F13) -> #REF! | G14: =SUM(G9:G13) -> #REF! | H14: =SUM(H9:H13) -> #REF!
C16: Test coverage | E16: =(D14+E14)*100/(H14-G14) -> #REF! | F16: %
C17: Test successful coverage | E17: =D14*100/(H14-G14) -> #REF! | F17: %

Sheet Login
A2: Module Code | B2: Login | K2: Pass
A3: Test requirement | B3: Verify login module | K3: Fail
A4: Tester | B4: hiennm23 | K4: Untesed
A5: Pass | B5: Fail | C5: Untested | D5: N/A | E5: Number of Test cases | K5: N/A
A6: =COUNTIF(G10:G1001,"Pass") -> 5 | B6: =COUNTIF(G10:G1001,"Fail") -> 0 | C6: =E6-D6-B6-A6 -> 0 | D6: =COUNTIF(G$10:G$1001,"N/A") -> 6 | E6: =COUNTA(A10:A1001) -> 11
A8: ID | B8: Test Case Description | C8: Test Case Procedure | D8: Expected Output | E8: Inter-test case Dependence | F8: TestData | G8: Result | H8: Test date | I8: Note | J8: Evidence
B9: Login
A10: [Login-01] | B10: Testing loading Login page | C10: 1. Access https://shopee.vn/ 2. Press [Đăng nhập] button | D10: 1. Login screen display 2. Following informations displayed: - Textbox Email/Sdt/ten dang nhap - Mat khau - button [Dang nhap] - button [Facebook] - button [Google] - hyperlink: Quen mat khau, dang nhap voi SMS, Dang ky - QR code: Đăng nhập với mã QR | E10: 1. System is online 2. Can connect with database | G10: Pass | H10: 45954 | J10: #VALUE!
A11: [Login-02] | B11: Verify login successfully | C11: 1. At Login page, enter following information: - Email: "manhhientqlk47@gmail.com" - Matkhau: "không tiết lộ được" 2. Press [Dang nhap] button | D11: 1. Shopee landing page is displaye. 2. Following information is displayed: - Shopee icon - account name: "hienmanhhd" - Search box - Slider - Product category, product list, flash sale… | E11: 1. [Login-01] 2. Account: - Email: "manhhientqlk47@gmail.com" - Matkhau: "không tiết lộ được" is registered before | F11: - Email: "manhhientqlk47@gmail.com" - Matkhau: "không tiết lộ được" | G11: Pass | H11: 45954 | J11: #VALUE!
A12: [Login-03] | B12: Verify login successfully - via Google account | C12: 1. At Login page -> click [Google] button 2. At [Lựa chọn tài khoản] select gmail account [manhhientqlk47@gmail.com] 3. At [Select login to Shopee] page, click [Tiếp tục] button | D12: 1. Shopee landing page is displaye. 2. Following information is displayed: - Shopee icon - account name: "hienmanhhd" - Search box - Slider - Product category, product list, flash sale… | E12: 1. [Login-01] 2. Account: - Email: "manhhientqlk47@gmail.com" - Matkhau: "không tiết lộ được" is registered before | F12: - Email: "manhhientqlk47@gmail.com" - Matkhau: "không tiết lộ được" | G12: Pass | H12: 45954 | J12: #VALUE!
A13: [Login-04] | B13: Verify login successfully - via Facebook | C13: 1. 2. | D13: 1. Shopee landing page is displaye. 2. Following information is displayed: - Shopee icon - account name: "hienmanhhd" - Search box - Slider - Product category, product list, flash sale… | G13: N/A
A14: [Login-05] | B14: Verify login fail - Invalid username | C14: 1. At Login page, enter following information: - Email: "manhhientqlkakjdhfouhfieurgfeurgfejbajkdv47@gmail.com" - Matkhau: "không tiết lộ được" 2. Press [Dang nhap] button | D14: 1. Error message display "Tên tài khoản của bạn hoặc Mật khẩu không đúng, vui lòng thử lại" 2. System not login | E14: 1. [Login-01] 2. Account: - Email: "manhhientqlkakjdhfouhfieurgfeurgfejbajkdv47@gmail.com" - Matkhau: "không tiết lộ được" is not registered before | F14: - Email: "manhhientqlkakjdhfouhfieurgfeurgfejbajkdv47@gmail.com" - Matkhau: "không tiết lộ được" | G14: Pass | H14: 45954 | J14: #VALUE!
A15: [Login-06] | B15: Verify login fail - Invalid password | C15: 1. At Login page, enter following information: - Email: "manhhientqlk47@gmail.com" - Matkhau: "Sai mật khẩu" 2. Press [Dang nhap] button | D15: 1. Error message display "Tên tài khoản của bạn hoặc Mật khẩu không đúng, vui lòng thử lại" 2. System not login | E15: 1. [Login-01] 2. Account: - Email: "manhhientqlk47@gmail.com" - Matkhau: "không tiết lộ được" is registered before. | F15: - Email: "manhhientqlk47@gmail.com" - Matkhau: "không tiết lộ được" | G15: Pass | H15: 45954 | J15: #VALUE!
B16: Quên mật khẩu
A17: [ResetPassword-01] | B17: <Test case 4> | G17: N/A
A18: [ResetPassword-02] | B18: <Test case 5> | G18: N/A
B19: Đăng ký
A20: [Register-01] | B20: <Test case 4> | G20: N/A
A21: [Register-02] | B21: <Test case 5> | G21: N/A
A22: [Register-03] | B22: <Test case 5> | G22: N/A

Sheet TEST_CASE_CURSOR
A2: Module Code | B2: Checklist Nhân sự | K2: Pass
A3: Test requirement | B3: Verify module Checklist Nhân sự (template, instance, confirm song song, tiến độ v2) | K3: Fail
A4: Tester | B4: hiennm23 | K4: Untesed
A5: Pass | B5: Fail | C5: Untested | D5: N/A | E5: Number of Test cases | K5: N/A
A6: 13 | B6: 3 | C6: 44 | D6: 0 | E6: 60
A8: ID | B8: Test Case Description | C8: Test Case Procedure | D8: Expected Output | E8: Inter-test case Dependence | F8: TestData | G8: Result | H8: Test date | I8: Note | J8: Evidence
B9: Danh sách checklist — /hrm/checklist
A10: [CL-List-01] | B10: ADMIN truy cập màn danh sách checklist | C10: 1. Đăng nhập tài khoản ADMIN 2. Truy cập menu HRM → Checklist (route /hrm/checklist) | D10: 1. Màn danh sách checklist hiển thị 2. ADMIN thấy toàn bộ instance trong hệ thống 3. Có đủ cột: Tên template, Nhân viên (fullName + accountName), StartDate, EndDate, Trạng thái, Tiến độ (done/total), Badge overdue (nếu có) | E10: 1. Tài khoản ADMIN hợp lệ 2. Đã có ít nhất 1 checklist instance | G10: Pass | H10: 2026-06-23 | I10: https://qlrv.democloud.xyz/hrm/checklist
A11: [CL-List-02] | B11: OFFICER chỉ thấy checklist liên quan mình | C11: 1. Đăng nhập tài khoản OFFICER (có task được giao) 2. Truy cập /hrm/checklist | D11: 1. Danh sách chỉ hiển thị instance có ít nhất 1 task với AssignedOfficerId = OFFICER hiện tại 2. Không hiển thị instance không liên quan | E11: 1. OFFICER được giao task trong instance A 2. Instance B không có task giao cho OFFICER này | F11: OFFICER: user có task assigned | G11: Pass | H11: 2026-06-23 | I11: https://qlrv.democloud.xyz/hrm/checklist
A12: [CL-List-03] | B12: EMPLOYEE chỉ thấy checklist của bản thân | C12: 1. Đăng nhập tài khoản EMPLOYEE 2. Truy cập /hrm/checklist | D12: 1. Danh sách chỉ hiển thị instance có EmployeeId = user hiện tại 2. Không hiển thị checklist của nhân viên khác | E12: 1. EMPLOYEE có instance riêng 2. Có instance của nhân viên khác trong DB | G12: Pass | H12: 2026-06-23 | I12: https://qlrv.democloud.xyz/hrm/checklist
A13: [CL-List-04] | B13: Hiển thị tiến độ doneTaskCount/totalTaskCount và % trên danh sách | C13: 1. Truy cập /hrm/checklist với instance có 7/10 task done | D13: 1. Cột tiến độ hiển thị 7/10 (hoặc 70%) 2. Không hiển thị pendingTaskCount (đã bỏ v2) | E13: [CL-List-01] Instance: doneTaskCount=7, totalTaskCount=10 | G13: Pass | H13: 2026-06-23 | I13: progress pattern in list
A14: [CL-List-05] | B14: Hiển thị badge overdueTaskCount | C14: 1. Truy cập danh sách với instance có task quá hạn chưa xử lý | D14: 1. Instance hiển thị badge/số overdueTaskCount > 0 2. Instance không overdue không hiển thị badge (hoặc = 0) | E14: Instance status Overdue hoặc có overdueTaskCount > 0 | G14: Pass | H14: 2026-06-23 | I14: overdue badge
A15: [CL-List-06] | B15: Filter danh sách theo Keyword | C15: 1. Tại màn danh sách, nhập Keyword (tên nhân viên / tên template) 2. Áp dụng filter | D15: 1. Danh sách chỉ hiển thị record khớp Keyword 2. API GET /api/checklist-assignment/getCheckList trả kết quả đã filter | E15: [CL-List-01] | G15: Untested
A16: [CL-List-07] | B16: Filter danh sách theo FromDate / ToDate | C16: 1. Chọn FromDate và ToDate 2. Áp dụng filter | D16: 1. Chỉ hiển thị instance có StartDate/EndDate trong khoảng chọn 2. Record ngoài khoảng không hiển thị | E16: [CL-List-01] | G16: Untested
A17: [CL-List-08] | B17: Filter danh sách theo Status | C17: 1. Chọn Status (Pending/InProgress/Completed/Overdue/Cancelled) 2. Áp dụng filter | D17: 1. Danh sách chỉ hiển thị instance có status tương ứng | E17: [CL-List-01] Có instance với nhiều status khác nhau | G17: Untested
A18: [CL-List-09] | B18: Filter theo EmployeeId | C18: 1. Chọn nhân viên cụ thể trong filter 2. Áp dụng | D18: 1. Chỉ hiển thị checklist của nhân viên được chọn | E18: [CL-List-01] | G18: Untested
A19: [CL-List-10] | B19: Phân trang danh sách checklist | C19: 1. Truy cập danh sách khi có > số record trên 1 trang 2. Chuyển trang 2, 3... | D19: 1. Trang 1 hiển thị đúng số record theo page size 2. Chuyển trang load đúng batch tiếp theo 3. total count khớp API | E19: [CL-List-01] Số instance > page size | G19: Untested
A20: [CL-List-11] | B20: Click checklist → mở màn chi tiết | C20: 1. Tại danh sách, click 1 dòng checklist | D20: 1. Navigate tới /hrm/checklist/:instanceId 2. Màn chi tiết load đúng instance | E20: [CL-List-01] | G20: Fail | H20: 2026-06-23 | I20: ADMIN:Pass; OFFICER:Fail; EMPLOYEE:Pass — ADMIN: ant-table-row click → https://qlrv.democloud.xyz/hrm/checklist/3283fdfe-e372-4af | OFFICER: Cannot open detail — empty table | EMPLOYEE: ant-table-row click → https://qlrv.democloud.xyz/hrm/checklist/3642145a-c309-4a1
B21: Chi tiết checklist — /hrm/checklist/:instanceId
A22: [CL-Detail-01] | B22: Hiển thị thông tin tổng quan instance | C22: 1. Mở chi tiết 1 checklist instance | D22: 1. Hiển thị: templateName, status, startDate, endDate 2. endDate = MAX(deadline) các task 3. progressPercent hiển thị (vòng tròn hoặc thanh %) | E22: [CL-List-11] | G22: Fail | H22: 2026-06-23 | I22: ADMIN:Pass; OFFICER:Fail; EMPLOYEE:Pass — ADMIN: https://qlrv.democloud.xyz/hrm/checklist/3283fdfe-e372-4afa-a6f3-db9c7fd29ad8 | OFFICER: Table has no data rows | EMPLOYEE: https://qlrv.democloud.xyz/hrm/checklist/3642145a-c309-4a19-b66c-a4e24cd710bd
A23: [CL-Detail-02] | B23: Hiển thị thông tin nhân viên (fullName, accountName, position, department) | C23: 1. Mở chi tiết checklist | D23: 1. Employee block hiển thị fullName từ user.FullName 2. accountName = AccessControlProfileName ?? Username 3. position và department hiển thị (JOIN bảng chức vụ/phòng ban) 4. Không null như v1 | E23: [CL-Detail-01] Nhân viên có phòng ban và chức vụ trên hệ thống | G23: Pass | H23: 2026-06-23 | I23: employee info
A24: [CL-Detail-03] | B24: Hiển thị sections và tasks theo SortOrder | C24: 1. Mở chi tiết checklist có nhiều section/task | D24: 1. Sections sắp theo sortOrder 2. Tasks trong mỗi section sắp theo sortOrder 3. Mỗi task: description, deadline, durationDays | E24: [CL-Detail-01] | G24: Pass | H24: 2026-06-23 | I24: ADMIN:Pass; EMPLOYEE:Pass — ADMIN: sections/tasks | EMPLOYEE: sections/tasks
A25: [CL-Detail-04] | B25: Hiển thị officer resolved (fullName + accountName) mỗi task | C25: 1. Mở chi tiết, xem task item | D25: 1. Hiển thị officerFullName và officerAccountName (JOIN user) 2. assignedOfficerId khớp task_item | E25: [CL-Detail-01] | G25: Pass | H25: 2026-06-23 | I25: ADMIN:Pass; EMPLOYEE:Pass — ADMIN: officer display | EMPLOYEE: officer display
A26: [CL-Detail-05] | B26: Hiển thị trạng thái OfficerStatus / EmployeeStatus mỗi task | C26: 1. Mở chi tiết với task ở các trạng thái khác nhau (Pending/Confirmed/Late/Undone) | D26: 1. UI hiển thị đúng trạng thái officer và employee độc lập 2. Hiển thị officerNote, employeeNote, lateReason nếu có 3. Hiển thị confirmedAt tương ứng | E26: [CL-Detail-01] Task mix nhiều status | G26: Pass | H26: 2026-06-23 | I26: ADMIN:Pass; EMPLOYEE:Pass — ADMIN: status display | EMPLOYEE: status display
A27: [CL-Detail-06] | B27: Hiển thị canOfficerUndo và officerUndoDeadline | C27: 1. Mở task officer đã confirm < 60 phút, employee chưa confirm 2. Mở task officer confirm > 60 phút hoặc employee đã confirm | D27: 1. Case 1: hiển thị nút Undo + deadline undo 2. Case 2: không hiển thị Undo (canOfficerUndo=false) | E27: [CL-Detail-01] | G27: Untested
A28: [CL-Detail-07] | B28: Hiển thị nhật ký (logs) read-only | C28: 1. Mở chi tiết checklist đã có log (CreateInstance, Confirm, ChangeOfficer...) | D28: 1. Danh sách log hiển thị createdAt, actorFullName, actorAccountName, action, detail 2. Không cho sửa/xóa log | E28: [CL-Detail-01] Instance đã có nhiều log | G28: Pass | H28: 2026-06-23 | I28: ADMIN:Pass; EMPLOYEE:Pass — ADMIN: logs | EMPLOYEE: logs
A29: [CL-Detail-08] | B29: Phân quyền xem chi tiết — OFFICER/EMPLOYEE không xem instance không liên quan | C29: 1. OFFICER truy cập URL chi tiết instance không có task mình 2. EMPLOYEE truy cập instance của người khác | D29: 1. Không cho xem (403/redirect/empty) 2. Không leak dữ liệu | E29: [CL-Detail-01] Có instance không liên quan | G29: Untested
B30: Quản lý template — /hrm/checklist/template (ADMIN)
A31: [CL-Tpl-01] | B31: ADMIN truy cập màn quản lý template | C31: 1. Đăng nhập ADMIN 2. Truy cập /hrm/checklist/template | D31: 1. Màn danh sách template hiển thị 2. OFFICER/EMPLOYEE không truy cập được (hoặc không thấy menu) | E31: Tài khoản ADMIN | G31: Pass | H31: 2026-06-23 | I31: snippet=CHECKINPRO admin admin Chấm công (cc) Thưởng/Phạt Việc cần làm ngay Sơ yếu lý lịch Số liệu lương Mẫu Checklist Checklist Tuyển dụng Test Online Đánh giá nhân viên Giảm trừ gia cảnh Thu gọn Quản lý tem
A32: [CL-Tpl-02] | B32: Danh sách template — filter và phân trang | C32: 1. Tại màn template, dùng filter và chuyển trang | D32: 1. GET /api/checklist-template/getList trả đúng filter + pagination 2. UI hiển thị Code, Name, IsActive | E32: [CL-Tpl-01] | G32: Pass | H32: 2026-06-23 | I32: List page visible
A33: [CL-Tpl-03] | B33: Tạo template mới — section + task + DefaultOfficerId | C33: 1. Click Tạo template 2. Nhập Code (không dấu), Name, Description 3. Thêm section (Name, SortOrder) 4. Thêm task (Description, DurationDays, SortOrder, DefaultOfficerId) 5. Lưu | D33: 1. POST /insert thành công 2. Template lưu đủ section/task 3. DefaultOfficerId lưu per task 4. Code unique, không dấu | E33: [CL-Tpl-01] Code VD: BHS_NhanSuMoi_2025 | G33: Pass | H33: 2026-06-23 | I33: Create form opened
A34: [CL-Tpl-04] | B34: Validate Code template trùng / có dấu | C34: 1. Tạo template Code đã tồn tại 2. Tạo template Code có dấu/ký tự không hợp lệ | D34: 1. Hiển thị lỗi validate, không tạo 2. DB không duplicate Code | E34: [CL-Tpl-03] | G34: Untested
A35: [CL-Tpl-05] | B35: Xem chi tiết template | C35: 1. Click 1 template trong danh sách | D35: 1. GET /getDetail trả sections + tasks + DefaultOfficerId 2. UI hiển thị đầy đủ cấu trúc template | E35: [CL-Tpl-01] | G35: Untested
A36: [CL-Tpl-06] | B36: Sửa template khi KHÔNG có instance active (status 0,1,3) | C36: 1. Chọn template chưa có instance Pending/InProgress/Overdue 2. Sửa Name/task/section → Lưu | D36: 1. POST /update thành công 2. Thay đổi được reflect | E36: [CL-Tpl-05] Template không có instance active | G36: Untested
A37: [CL-Tpl-07] | B37: Không cho sửa template khi CÓ instance active | C37: 1. Chọn template đã có instance status 0/1/3 2. Thử sửa và lưu | D37: 1. BE từ chối (BR-08) 2. UI hiển thị thông báo lỗi / disable edit | E37: [CL-Tpl-05] Template có instance InProgress | G37: Untested
A38: [CL-Tpl-08] | B38: Bật/tắt template (toggleActive) | C38: 1. Toggle IsActive template từ ON → OFF 2. Toggle OFF → ON | D38: 1. PATCH /toggleActive cập nhật IsActive 2. Template OFF không dùng được khi tạo instance mới (nếu FE enforce) | E38: [CL-Tpl-01] | G38: Untested
B39: Tạo checklist instance (ADMIN)
A40: [CL-Create-01] | B40: ADMIN tạo checklist — 1 nhân viên | C40: 1. ADMIN chọn Tạo checklist 2. Chọn Template + 1 Employee + StartDate 3. (Nếu cần) chọn fallback AssignedOfficer 4. Submit | D40: 1. POST /insertBulk thành công 2. Sinh checklist_instance + task_item 3. Deadline mỗi task = StartDate + DurationDays 4. EndDate instance = MAX deadline 5. Status = Pending (0) | E40: [CL-Tpl-03] Template active, employee chưa có instance trùng | F40: templateId, startDate, employeeIds[1] | G40: Untested
A41: [CL-Create-02] | B41: ADMIN tạo checklist — nhiều nhân viên (bulk) | C41: 1. Chọn cùng template + StartDate + nhiều employeeIds 2. Submit | D41: 1. Tạo N instance (1 per employee) 2. Mỗi instance có đủ task từ template | E41: [CL-Create-01] employeeIds: 2+ nhân viên | G41: Untested
A42: [CL-Create-03] | B42: Gán officer per-task từ DefaultOfficerId template | C42: 1. Tạo instance từ template task có DefaultOfficerId 2. Kiểm tra task_item.AssignedOfficerId | D42: 1. AssignedOfficerId = template_task.DefaultOfficerId (BR-12) 2. Không cần gán tay từng task | E42: [CL-Tpl-03] Task có DefaultOfficerId | G42: Untested
...
